<?xml version='1.0'?>
<sdf version='1.4'>
  <model name="robot_soccer_00">
  
  <static>false</static>
    
    <link name='chassis'>
      <pose>0 0 0 0 0 0</pose>
      <collision name='collision'>
        <geometry>
          <mesh>
            <uri>./hex.dae</uri>
          </mesh>
        </geometry>
      </collision>

      <visual name='visual'>
        <geometry>
          <mesh>
            <uri>./hex.dae</uri>
          </mesh>
        </geometry>
      </visual>

    </link>

    <link name='right_wheel'>
      <pose>-.05 .07 -.038618 0 1.5707 -1.1</pose>
      <collision name="right_wheel_collision">
        <geometry>
          <cylinder>
            <radius>.05</radius>
            <length>.02</length>
          </cylinder>
        </geometry>
      </collision>
      <visual name="right_wheel_visual">
        <geometry>
          <cylinder>
            <radius>.05</radius>
            <length>.02</length>
          </cylinder>
        </geometry>
      </visual>
    </link>

    <link name='left_wheel'>
      <pose>-.05 -.07 -.038618 0 1.5707 1.1</pose>
      <collision name="left_wheel_collision">
        <geometry>
          <cylinder>
            <radius>.05</radius>
            <length>.02</length>
          </cylinder>
        </geometry>
      </collision>
      <visual name="left_wheel_visual">
        <geometry>
          <cylinder>
            <radius>.05</radius>
            <length>.02</length>
          </cylinder>
        </geometry>
      </visual>
    </link>

    <link name='back_wheel'>
      <pose>.1 0 -.038618 0 1.5707 0</pose>
      <collision name="back_wheel_collision">
        <geometry>
          <cylinder>
            <radius>.05</radius>
            <length>.02</length>
          </cylinder>
        </geometry>
      </collision>
      <visual name="back_wheel_visual">
        <geometry>
          <cylinder>
            <radius>.05</radius>
            <length>.02</length>
          </cylinder>
        </geometry>
      </visual>
    </link>

  <joint type="revolute2" name="left_wheel_hinge">
    <pose>-.05 -.07 -.038618 -1.1 1.5707 0</pose>
    <child>left_wheel</child>
    <parent>chassis</parent>
    <axis>
      <xyz>1 1 0</xyz>
    </axis>
  </joint>

  <joint type="revolute2" name="right_wheel_hinge">
    <pose>-.05 .07 -.038618 1.1 1.5707 0</pose>
    <child>right_wheel</child>
    <parent>chassis</parent>
    <axis>
      <xyz>1 1 0</xyz>
    </axis>
  </joint>

  <joint type="revolute2" name="back_wheel_hinge">
    <pose>.1 0 0 0 1.5707 0</pose>
    <child>back_wheel</child>
    <parent>chassis</parent>
    <axis>
      <xyz>1 1 0</xyz>
    </axis>
  </joint>

  </model>
</sdf>
