<?xml version='1.0'?>
<sdf version='1.4'>
  <model name="robot_soccer_01">
  
  <static>false</static>
    
    <link name='chassis'>
      <pose>0 0 0 0 0 0</pose>
      <collision name='collision'>
        <geometry>
          <mesh>
            <uri>./hex.dae</uri>
          </mesh>
        </geometry>
      </collision>

      <visual name='visual'>
        <geometry>
          <mesh>
            <uri>./hex.dae</uri>
          </mesh>
        </geometry>
      </visual>

    </link>

    <link name='right_wheel'>
      <pose>-.05 .07 -.038618 0 1.5707 -1.1</pose>
      <collision name="right_wheel_caster_collision">
      <geometry>
        <sphere>
          <radius>.03</radius>
        </sphere>
      </geometry>

      <surface>
        <friction>
          <ode>
            <mu>0</mu>
            <mu2>0</mu2>
            <slip1>1.0</slip1>
            <slip2>1.0</slip2>
          </ode>
        </friction>
      </surface>
    </collision>

    <visual name="right_wheel_visual">
      <pose>-.05 .07 -.038618 0 1.5707 -1.1</pose>
      <geometry>
        <sphere>
          <radius>.03</radius>
        </sphere>
      </geometry>
    </visual>

    </link>

    <link name='left_wheel'>
      <pose>-.05 -.07 -.038618 0 1.5707 1.1</pose>
      <collision name="left_wheel_caster_collision">
      <geometry>
        <sphere>
          <radius>.03</radius>
        </sphere>
      </geometry>      

      <surface>
        <friction>
          <ode>
            <mu>0</mu>
            <mu2>0</mu2>
            <slip1>1.0</slip1>
            <slip2>1.0</slip2>
          </ode>
        </friction>
      </surface>
    </collision>

    <visual name="left_wheel_visual">
      <pose>-.05 -.07 -.038618 0 1.5707 1.1</pose>
      <geometry>
        <sphere>
          <radius>.03</radius>
        </sphere>
      </geometry>
    </visual>
    </link>

    <link name='back_wheel'>
      <pose>.1 0 -.038618 0 1.5707 0</pose>
      <collision name="back_wheel_caster_collision">
      <geometry>
        <sphere>
          <radius>.03</radius>
        </sphere>
      </geometry>      

      <surface>
        <friction>
          <ode>
            <mu>0</mu>
            <mu2>0</mu2>
            <slip1>1.0</slip1>
            <slip2>1.0</slip2>
          </ode>
        </friction>
      </surface>
    </collision>

    <visual name="back_wheel_visual">
      <pose>.1 0 -.038618 0 1.5707 0</pose>
      <geometry>
        <sphere>
          <radius>.03</radius>
        </sphere>
      </geometry>
    </visual>
    </link>

  <joint type="revolute2" name="left_wheel_hinge">
    <pose>-.05 -.07 -.038618 -1.1 1.5707 0</pose>
    <child>left_wheel</child>
    <parent>chassis</parent>
    <axis>
      <xyz>1 1 0</xyz>
    </axis>
  </joint>

  <joint type="revolute2" name="right_wheel_hinge">
    <pose>-.05 .07 -.038618 1.1 1.5707 0</pose>
    <child>right_wheel</child>
    <parent>chassis</parent>
    <axis>
      <xyz>1 1 0</xyz>
    </axis>
  </joint>

  <joint type="revolute2" name="back_wheel_hinge">
    <pose>.1 0 0 0 1.5707 0</pose>
    <child>back_wheel</child>
    <parent>chassis</parent>
    <axis>
      <xyz>1 1 0</xyz>
    </axis>
  </joint>

  </model>
</sdf>
